Workbook

Sheet Read me
A1: IntelliStride - participant sheet
A4: How to use
A5: 1 | B5: Participants tab: type age, sex, height, weight and foot size in the yellow cells. BMI and category fill in by themselves.
A6: 2 | B6: Readings tab: for each person there are 8 reading slots. Type the values from the shoe or the dashboard into the yellow cells. Acceleration magnitude, angular-velocity magnitude, tilt, sudden change, risk score and risk level calculate automatically.
A7: 3 | B7: Summary tab: one line per person (height, weight, BMI, readings logged, peak and mean risk score, highest level). It updates as you fill the other tabs.
A8: 4 | B8: Reference tab: the thresholds and points the risk score uses, copied from the dashboard code (fall-risk.js). Change a threshold there and every score follows.

Sheet Participants
A1: Participants
A2: SAMPLE VALUES for demonstration - heights, weights and readings below were not measured on these people.
A5: # | B5: Name | C5: Age (yrs) | D5: Sex | E5: Height (cm) | F5: Weight (kg) | G5: BMI (kg/m2) | H5: BMI category (WHO adult) | I5: Foot size (UK) | J5: Tested on | K5: Notes
A6: 1 | B6: Vidula Nijhawan | C6: 20 | D6: Female | E6: 160 | F6: 52 | G6: =IF(AND(ISNUMBER(E6),ISNUMBER(F6),E6>0),F6/(E6/100)^2,"") -> 20.3125 | H6: =IF(G6="","",IF(G6<18.5,"Underweight",IF(G6<25,"Normal",IF(G6<30,"Overweight","Obese")))) -> Normal | I6: 5 | J6: 30-Sept-2026 | K6: Normal walk
A7: 2 | B7: Rishika Gupta | C7: 20 | D7: Female | E7: 163 | F7: 55 | G7: =IF(AND(ISNUMBER(E7),ISNUMBER(F7),E7>0),F7/(E7/100)^2,"") -> 20.700817 | H7: =IF(G7="","",IF(G7<18.5,"Underweight",IF(G7<25,"Normal",IF(G7<30,"Overweight","Obese")))) -> Normal | I7: 6 | J7: 30-Sept-2026 | K7: Brisk walk with a turn
A8: 3 | B8: Vishav Gupta | C8: 21 | D8: Male | E8: 174 | F8: 68 | G8: =IF(AND(ISNUMBER(E8),ISNUMBER(F8),E8>0),F8/(E8/100)^2,"") -> 22.460034 | H8: =IF(G8="","",IF(G8<18.5,"Underweight",IF(G8<25,"Normal",IF(G8<30,"Overweight","Obese")))) -> Normal | I8: 8 | J8: 30-Sept-2026 | K8: Normal walk
A9: 4 | B9: Vedant Singh | C9: 21 | D9: Male | E9: 178 | F9: 72 | G9: =IF(AND(ISNUMBER(E9),ISNUMBER(F9),E9>0),F9/(E9/100)^2,"") -> 22.724403 | H9: =IF(G9="","",IF(G9<18.5,"Underweight",IF(G9<25,"Normal",IF(G9<30,"Overweight","Obese")))) -> Normal | I9: 9 | J9: 30-Sept-2026 | K9: Standing, weight shifting
A10: 5 | B10: Daksh Jain | C10: 20 | D10: Male | E10: 172 | F10: 64 | G10: =IF(AND(ISNUMBER(E10),ISNUMBER(F10),E10>0),F10/(E10/100)^2,"") -> 21.633315 | H10: =IF(G10="","",IF(G10<18.5,"Underweight",IF(G10<25,"Normal",IF(G10<30,"Overweight","Obese")))) -> Normal | I10: 8 | J10: 46300 | K10: Staged stumble (demo only)
A11: 6 | B11: Sudeep | C11: 22 | D11: Male | E11: 176 | F11: 70 | G11: =IF(AND(ISNUMBER(E11),ISNUMBER(F11),E11>0),F11/(E11/100)^2,"") -> 22.59814 | H11: =IF(G11="","",IF(G11<18.5,"Underweight",IF(G11<25,"Normal",IF(G11<30,"Overweight","Obese")))) -> Normal | I11: 9 | J11: 46300 | K11: Normal walk
A12: 7 | B12: Dhairya | C12: 21 | D12: Male | E12: 170 | F12: 62 | G12: =IF(AND(ISNUMBER(E12),ISNUMBER(F12),E12>0),F12/(E12/100)^2,"") -> 21.453287 | H12: =IF(G12="","",IF(G12<18.5,"Underweight",IF(G12<25,"Normal",IF(G12<30,"Overweight","Obese")))) -> Normal | I12: 8 | J12: 46300 | K12: Brisk walk with a turn
A13: 8 | B13: Sanjana | C13: 20 | D13: Female | E13: 158 | F13: 50 | G13: =IF(AND(ISNUMBER(E13),ISNUMBER(F13),E13>0),F13/(E13/100)^2,"") -> 20.028842 | H13: =IF(G13="","",IF(G13<18.5,"Underweight",IF(G13<25,"Normal",IF(G13<30,"Overweight","Obese")))) -> Normal | I13: 5 | J13: 46300 | K13: Normal walk
A14: 9 | B14: Aniket | C14: 21 | D14: Male | E14: 180 | F14: 76 | G14: =IF(AND(ISNUMBER(E14),ISNUMBER(F14),E14>0),F14/(E14/100)^2,"") -> 23.45679 | H14: =IF(G14="","",IF(G14<18.5,"Underweight",IF(G14<25,"Normal",IF(G14<30,"Overweight","Obese")))) -> Normal | I14: 9 | J14: 46300 | K14: Seated, resting
A15: 10 | B15: Raghav Garg | C15: 21 | D15: Male | E15: 175 | F15: 78 | G15: =IF(AND(ISNUMBER(E15),ISNUMBER(F15),E15>0),F15/(E15/100)^2,"") -> 25.469388 | H15: =IF(G15="","",IF(G15<18.5,"Underweight",IF(G15<25,"Normal",IF(G15<30,"Overweight","Obese")))) -> Overweight | I15: 9 | J15: 46304 | K15: Normal walk
A16: 11 | B16: Kushal Thakur | C16: 22 | D16: Male | E16: 183 | F16: 82 | G16: =IF(AND(ISNUMBER(E16),ISNUMBER(F16),E16>0),F16/(E16/100)^2,"") -> 24.485652 | H16: =IF(G16="","",IF(G16<18.5,"Underweight",IF(G16<25,"Normal",IF(G16<30,"Overweight","Obese")))) -> Normal | I16: 10 | J16: 46304 | K16: Brisk walk with a turn
A17: 12 | B17: Manjot Singh | C17: 21 | D17: Male | E17: 177 | F17: 67 | G17: =IF(AND(ISNUMBER(E17),ISNUMBER(F17),E17>0),F17/(E17/100)^2,"") -> 21.385936 | H17: =IF(G17="","",IF(G17<18.5,"Underweight",IF(G17<25,"Normal",IF(G17<30,"Overweight","Obese")))) -> Normal | I17: 9 | J17: 46304 | K17: Standing, weight shifting
A18: 13 | B18: Tejnoor Singh | C18: 20 | D18: Male | E18: 173 | F18: 60 | G18: =IF(AND(ISNUMBER(E18),ISNUMBER(F18),E18>0),F18/(E18/100)^2,"") -> 20.047446 | H18: =IF(G18="","",IF(G18<18.5,"Underweight",IF(G18<25,"Normal",IF(G18<30,"Overweight","Obese")))) -> Normal | I18: 8 | J18: 46304 | K18: Normal walk
A19: 14 | B19: Ramit Joshi | C19: 21 | D19: Male | E19: 169 | F19: 58 | G19: =IF(AND(ISNUMBER(E19),ISNUMBER(F19),E19>0),F19/(E19/100)^2,"") -> 20.307412 | H19: =IF(G19="","",IF(G19<18.5,"Underweight",IF(G19<25,"Normal",IF(G19<30,"Overweight","Obese")))) -> Normal | I19: 7 | J19: 46306 | K19: Seated, resting
A20: 15 | B20: Kirtan Borana | C20: 22 | D20: Male | E20: 171 | F20: 74 | G20: =IF(AND(ISNUMBER(E20),ISNUMBER(F20),E20>0),F20/(E20/100)^2,"") -> 25.306932 | H20: =IF(G20="","",IF(G20<18.5,"Underweight",IF(G20<25,"Normal",IF(G20<30,"Overweight","Obese")))) -> Overweight | I20: 8 | J20: 46306 | K20: Normal walk
A22: BMI = weight / height squared; categories are the WHO adult bands (under 18.5, 18.5-24.9, 25-29.9, 30 and over) and do not apply under 18.

Sheet Readings
A1: Readings - 8 slots per person
A2: SAMPLE VALUES for demonstration - heights, weights and readings below were not measured on these people.
A3: Units: FSR raw ADC 0-4095 (uncalibrated) | accel g | gyro deg/s | pitch, roll deg | distance cm. Prototype score, not clinically validated.
A5: Person # | B5: Name | C5: Reading | D5: Time (HH:MM:SS) | E5: Phase | F5: FSR fore-foot | G5: FSR mid-foot | H5: FSR hind-foot | I5: Accel x (g) | J5: Accel y (g) | K5: Accel z (g) | L5: Gyro x (deg/s) | M5: Gyro y (deg/s) | N5: Gyro z (deg/s) | O5: Pitch (deg) | P5: Roll (deg) | Q5: Distance (cm) | R5: GPS sats | S5: GPS fix (Y/N) | T5: Accel mag (g) | U5: Gyro mag (deg/s) | V5: Tilt (deg) | W5: Sudden change (g) | X5: Risk score (0-100) | Y5: Risk level
A6: 1 | B6: =INDEX(Participants!$B$6:$B$20,A6) -> Vidula Nijhawan | C6: 1 | D6: 0.41104167 | E6: Heel strike | F6: 318 | G6: 435 | H6: 2565 | I6: 0.08 | J6: 0.07 | K6: 1.02 | L6: 3.1 | M6: 0.5 | N6: 2.5 | O6: 3.4 | P6: 1.1 | Q6: 203 | R6: 7 | S6: Y | T6: =IF(COUNT(I6:K6)<3,"",SQRT(I6^2+J6^2+K6^2)) -> 1.0255243 | U6: =IF(COUNT(L6:N6)<3,"",SQRT(L6^2+M6^2+N6^2)) -> 4.0137264 | V6: =IF(COUNT(O6:P6)<2,"",SQRT(O6^2+P6^2)) -> 3.5735137 | W6: =IF(T6="","",0) -> 0 | X6: =IF(OR(T6="",U6="",V6=""),"",MIN(100,IF(T6>=Reference!$B$9,Reference!$C$9,IF(T6>=Reference!$B$8,Reference!$C$8,IF(T6>=Reference!$B$7,Reference!$C$7,0)))+IF(U6>=Reference!$B$12,Reference!$C$12,IF(U6>=Reference!$B$11,Reference!$C$11,IF(U6>=Reference!$B$10,Reference!$C$10,0)))+IF(W6>=Reference!$B$13,Reference!$C$13,0)+IF(V6>=Reference!$B$15,Reference!$C$15,IF(V6>=Reference!$B$14,Reference!$C$14,0)))) -> 0 | Y6: =IF(X6="","",IF(X6>=Reference!$B$6,"HIGH",IF(X6>Reference!$B$5,"MODERATE","LOW"))) -> LOW
A7: 1 | B7: =INDEX(Participants!$B$6:$B$20,A7) -> Vidula Nijhawan | C7: 2 | D7: 0.41113426 | E7: Foot flat | F7: 980 | G7: 1422 | H7: 2401 | I7: 0.05 | J7: -0.05 | K7: 0.98 | L7: 2.4 | M7: 0.7 | N7: 1.1 | O7: 1.3 | P7: 0.7 | Q7: 192 | R7: 7 | S7: Y | T7: =IF(COUNT(I7:K7)<3,"",SQRT(I7^2+J7^2+K7^2)) -> 0.98254771 | U7: =IF(COUNT(L7:N7)<3,"",SQRT(L7^2+M7^2+N7^2)) -> 2.7313001 | V7: =IF(COUNT(O7:P7)<2,"",SQRT(O7^2+P7^2)) -> 1.4764823 | W7: =IF(T7="","",IF(T6="",0,ABS(T7-T6))) -> 0.042976547 | X7: =IF(OR(T7="",U7="",V7=""),"",MIN(100,IF(T7>=Reference!$B$9,Reference!$C$9,IF(T7>=Reference!$B$8,Reference!$C$8,IF(T7>=Reference!$B$7,Reference!$C$7,0)))+IF(U7>=Reference!$B$12,Reference!$C$12,IF(U7>=Reference!$B$11,Reference!$C$11,IF(U7>=Reference!$B$10,Reference!$C$10,0)))+IF(W7>=Reference!$B$13,Reference!$C$13,0)+IF(V7>=Reference!$B$15,Reference!$C$15,IF(V7>=Reference!$B$14,Reference!$C$14,0)))) -> 0 | Y7: =IF(X7="","",IF(X7>=Reference!$B$6,"HIGH",IF(X7>Reference!$B$5,"MODERATE","LOW"))) -> LOW
A8: 1 | B8: =INDEX(Participants!$B$6:$B$20,A8) -> Vidula Nijhawan | C8: 3 | D8: 0.4112037 | E8: Mid stance | F8: 1693 | G8: 1955 | H8: 1067 | I8: 0.02 | J8: 0.05 | K8: 1.07 | L8: 2 | M8: -0.2 | N8: 0.3 | O8: 0.8 | P8: 0.5 | Q8: 198 | R8: 7 | S8: Y | T8: =IF(COUNT(I8:K8)<3,"",SQRT(I8^2+J8^2+K8^2)) -> 1.0713543 | U8: =IF(COUNT(L8:N8)<3,"",SQRT(L8^2+M8^2+N8^2)) -> 2.0322401 | V8: =IF(COUNT(O8:P8)<2,"",SQRT(O8^2+P8^2)) -> 0.94339811 | W8: =IF(T8="","",IF(T7="",0,ABS(T8-T7))) -> 0.088806574 | X8: =IF(OR(T8="",U8="",V8=""),"",MIN(100,IF(T8>=Reference!$B$9,Reference!$C$9,IF(T8>=Reference!$B$8,Reference!$C$8,IF(T8>=Reference!$B$7,Reference!$C$7,0)))+IF(U8>=Reference!$B$12,Reference!$C$12,IF(U8>=Reference!$B$11,Reference!$C$11,IF(U8>=Reference!$B$10,Reference!$C$10,0)))+IF(W8>=Reference!$B$13,Reference!$C$13,0)+IF(V8>=Reference!$B$15,Reference!$C$15,IF(V8>=Reference!$B$14,Reference!$C$14,0)))) -> 0 | Y8: =IF(X8="","",IF(X8>=Reference!$B$6,"HIGH",IF(X8>Reference!$B$5,"MODERATE","LOW"))) -> LOW
A9: 1 | B9: =INDEX(Participants!$B$6:$B$20,A9) -> Vidula Nijhawan | C9: 4 | D9: 0.41131944 | E9: Toe off | F9: 2571 | G9: 1042 | H9: 290 | I9: -0.11 | J9: 0.08 | K9: 1.11 | L9: 9.7 | M9: 3 | N9: 3.6 | O9: -5.9 | P9: 1.7 | Q9: 179 | R9: 7 | S9: Y | T9: =IF(COUNT(I9:K9)<3,"",SQRT(I9^2+J9^2+K9^2)) -> 1.1183023 | U9: =IF(COUNT(L9:N9)<3,"",SQRT(L9^2+M9^2+N9^2)) -> 10.772651 | V9: =IF(COUNT(O9:P9)<2,"",SQRT(O9^2+P9^2)) -> 6.1400326 | W9: =IF(T9="","",IF(T8="",0,ABS(T9-T8))) -> 0.046948002 | X9: =IF(OR(T9="",U9="",V9=""),"",MIN(100,IF(T9>=Reference!$B$9,Reference!$C$9,IF(T9>=Reference!$B$8,Reference!$C$8,IF(T9>=Reference!$B$7,Reference!$C$7,0)))+IF(U9>=Reference!$B$12,Reference!$C$12,IF(U9>=Reference!$B$11,Reference!$C$11,IF(U9>=Reference!$B$10,Reference!$C$10,0)))+IF(W9>=Reference!$B$13,Reference!$C$13,0)+IF(V9>=Reference!$B$15,Reference!$C$15,IF(V9>=Reference!$B$14,Reference!$C$14,0)))) -> 0 | Y9: =IF(X9="","",IF(X9>=Reference!$B$6,"HIGH",IF(X9>Reference!$B$5,"MODERATE","LOW"))) -> LOW
A10: 1 | B10: =INDEX(Participants!$B$6:$B$20,A10) -> Vidula Nijhawan | C10: 5 | D10: 0.41137731 | E10: Swing | F10: 100 | G10: 67 | H10: 42 | I10: 0.05 | J10: 0.01 | K10: 0.96 | L10: 12.7 | M10: 5.5 | N10: 7.1 | O10: -9.4 | P10: 2.5 | Q10: 177 | R10: 6 | S10: Y | T10: =IF(COUNT(I10:K10)<3,"",SQRT(I10^2+J10^2+K10^2)) -> 0.96135321 | U10: =IF(COUNT(L10:N10)<3,"",SQRT(L10^2+M10^2+N10^2)) -> 15.554742 | V10: =IF(COUNT(O10:P10)<2,"",SQRT(O10^2+P10^2)) -> 9.7267672 | W10: =IF(T10="","",IF(T9="",0,ABS(T10-T9))) -> 0.15694907 | X10: =IF(OR(T10="",U10="",V10=""),"",MIN(100,IF(T10>=Reference!$B$9,Reference!$C$9,IF(T10>=Reference!$B$8,Reference!$C$8,IF(T10>=Reference!$B$7,Reference!$C$7,0)))+IF(U10>=Reference!$B$12,Reference!$C$12,IF(U10>=Reference!$B$11,Reference!$C$11,IF(U10>=Reference!$B$10,Reference!$C$10,0)))+IF(W10>=Reference!$B$13,Reference!$C$13,0)+IF(V10>=Reference!$B$15,Reference!$C$15,IF(V10>=Reference!$B$14,Reference!$C$14,0)))) -> 5 | Y10: =IF(X10="","",IF(X10>=Reference!$B$6,"HIGH",IF(X10>Reference!$B$5,"MODERATE","LOW"))) -> LOW
A11: 1 | B11: =INDEX(Participants!$B$6:$B$20,A11) -> Vidula Nijhawan | C11: 6 | D11: 0.41148148 | E11: Heel strike | F11: 368 | G11: 429 | H11: 2685 | I11: 0.1 | J11: 0.04 | K11: 1.05 | L11: 4.8 | M11: 2.1 | N11: 1.9 | O11: 3.2 | P11: 1.1 | Q11: 252 | R11: 8 | S11: Y | T11: =IF(COUNT(I11:K11)<3,"",SQRT(I11^2+J11^2+K11^2)) -> 1.0555094 | U11: =IF(COUNT(L11:N11)<3,"",SQRT(L11^2+M11^2+N11^2)) -> 5.5731499 | V11: =IF(COUNT(O11:P11)<2,"",SQRT(O11^2+P11^2)) -> 3.3837849 | W11: =IF(T11="","",IF(T10="",0,ABS(T11-T10))) -> 0.094156143 | X11: =IF(OR(T11="",U11="",V11=""),"",MIN(100,IF(T11>=Reference!$B$9,Reference!$C$9,IF(T11>=Reference!$B$8,Reference!$C$8,IF(T11>=Reference!$B$7,Reference!$C$7,0)))+IF(U11>=Reference!$B$12,Reference!$C$12,IF(U11>=Reference!$B$11,Reference!$C$11,IF(U11>=Reference!$B$10,Reference!$C$10,0)))+IF(W11>=Reference!$B$13,Reference!$C$13,0)+IF(V11>=Reference!$B$15,Reference!$C$15,IF(V11>=Reference!$B$14,Reference!$C$14,0)))) -> 0 | Y11: =IF(X11="","",IF(X11>=Reference!$B$6,"HIGH",IF(X11>Reference!$B$5,"MODERATE","LOW"))) -> LOW
A12: 1 | B12: =INDEX(Participants!$B$6:$B$20,A12) -> Vidula Nijhawan | C12: 7 | D12: 0.41155093 | E12: Foot flat | F12: 971 | G12: 1387 | H12: 2295 | I12: 0.02 | J12: -0.05 | K12: 1.02 | L12: 2.3 | M12: -0.1 | N12: 0.7 | O12: 1.1 | P12: 0.7 | Q12: 242 | R12: 6 | S12: Y | T12: =IF(COUNT(I12:K12)<3,"",SQRT(I12^2+J12^2+K12^2)) -> 1.0214206 | U12: =IF(COUNT(L12:N12)<3,"",SQRT(L12^2+M12^2+N12^2)) -> 2.4062419 | V12: =IF(COUNT(O12:P12)<2,"",SQRT(O12^2+P12^2)) -> 1.3038405 | W12: =IF(T12="","",IF(T11="",0,ABS(T12-T11))) -> 0.034088776 | X12: =IF(OR(T12="",U12="",V12=""),"",MIN(100,IF(T12>=Reference!$B$9,Reference!$C$9,IF(T12>=Reference!$B$8,Reference!$C$8,IF(T12>=Reference!$B$7,Reference!$C$7,0)))+IF(U12>=Reference!$B$12,Reference!$C$12,IF(U12>=Reference!$B$11,Reference!$C$11,IF(U12>=Reference!$B$10,Reference!$C$10,0)))+IF(W12>=Reference!$B$13,Reference!$C$13,0)+IF(V12>=Reference!$B$15,Reference!$C$15,IF(V12>=Reference!$B$14,Reference!$C$14,0)))) -> 0 | Y12: =IF(X12="","",IF(X12>=Reference!$B$6,"HIGH",IF(X12>Reference!$B$5,"MODERATE","LOW"))) -> LOW
A13: 1 | B13: =INDEX(Participants!$B$6:$B$20,A13) -> Vidula Nijhawan | C13: 8 | D13: 0.41167824 | E13: Toe off | F13: 2724 | G13: 1011 | H13: 231 | I13: -0.09 | J13: 0.07 | K13: 1.07 | L13: 10 | M13: 3.1 | N13: 3.5 | O13: -5.8 | P13: 1.8 | Q13: 202 | R13: 7 | S13: Y | T13: =IF(COUNT(I13:K13)<3,"",SQRT(I13^2+J13^2+K13^2)) -> 1.0760576 | U13: =IF(COUNT(L13:N13)<3,"",SQRT(L13^2+M13^2+N13^2)) -> 11.039022 | V13: =IF(COUNT(O13:P13)<2,"",SQRT(O13^2+P13^2)) -> 6.0728906 | W13: =IF(T13="","",IF(T12="",0,ABS(T13-T12))) -> 0.05463704 | X13: =IF(OR(T13="",U13="",V13=""),"",MIN(100,IF(T13>=Reference!$B$9,Reference!$C$9,IF(T13>=Reference!$B$8,Reference!$C$8,IF(T13>=Reference!$B$7,Reference!$C$7,0)))+IF(U13>=Reference!$B$12,Reference!$C$12,IF(U13>=Reference!$B$11,Reference!$C$11,IF(U13>=Reference!$B$10,Reference!$C$10,0)))+IF(W13>=Reference!$B$13,Reference!$C$13,0)+IF(V13>=Reference!$B$15,Reference!$C$15,IF(V13>=Reference!$B$14,Reference!$C$14,0)))) -> 0 | Y13: =IF(X13="","",IF(X13>=Reference!$B$6,"HIGH",IF(X13>Reference!$B$5,"MODERATE","LOW"))) -> LOW
A14: 2 | B14: =INDEX(Participants!$B$6:$B$20,A14) -> Rishika Gupta | C14: 1 | D14: 0.34915509 | E14: Heel strike | F14: 601 | G14: 803 | H14: 3554 | I14: 0.2 | J14: 0.13 | K14: 1.18 | L14: 20.4 | M14: 10.9 | N14: 9.4 | O14: 4.5 | P14: 2.2 | Q14: 160 | R14: 8 | S14: Y | T14: =IF(COUNT(I14:K14)<3,"",SQRT(I14^2+J14^2+K14^2)) -> 1.2038688 | U14: =IF(COUNT(L14:N14)<3,"",SQRT(L14^2+M14^2+N14^2)) -> 24.966578 | V14: =IF(COUNT(O14:P14)<2,"",SQRT(O14^2+P14^2)) -> 5.0089919 | W14: =IF(T14="","",0) -> 0 | X14: =IF(OR(T14="",U14="",V14=""),"",MIN(100,IF(T14>=Reference!$B$9,Reference!$C$9,IF(T14>=Reference!$B$8,Reference!$C$8,IF(T14>=Reference!$B$7,Reference!$C$7,0)))+IF(U14>=Reference!$B$12,Reference!$C$12,IF(U14>=Reference!$B$11,Reference!$C$11,IF(U14>=Reference!$B$10,Reference!$C$10,0)))+IF(W14>=Reference!$B$13,Reference!$C$13,0)+IF(V14>=Reference!$B$15,Reference!$C$15,IF(V14>=Reference!$B$14,Reference!$C$14,0)))) -> 8 | Y14: =IF(X14="","",IF(X14>=Reference!$B$6,"HIGH",IF(X14>Reference!$B$5,"MODERATE","LOW"))) -> LOW
A15: 2 | B15: =INDEX(Participants!$B$6:$B$20,A15) -> Rishika Gupta | C15: 2 | D15: 0.34922454 | E15: Foot flat | F15: 1622 | G15: 2330 | H15: 2725 | I15: 0.16 | J15: -0.07 | K15: 1.12 | L15: 12.4 | M15: 8.5 | N15: 5 | O15: 2.6 | P15: 1.6 | Q15: 144 | R15: 9 | S15: Y | T15: =IF(COUNT(I15:K15)<3,"",SQRT(I15^2+J15^2+K15^2)) -> 1.1335343 | U15: =IF(COUNT(L15:N15)<3,"",SQRT(L15^2+M15^2+N15^2)) -> 15.843295 | V15: =IF(COUNT(O15:P15)<2,"",SQRT(O15^2+P15^2)) -> 3.0528675 | W15: =IF(T15="","",IF(T14="",0,ABS(T15-T14))) -> 0.070334468 | X15: =IF(OR(T15="",U15="",V15=""),"",MIN(100,IF(T15>=Reference!$B$9,Reference!$C$9,IF(T15>=Reference!$B$8,Reference!$C$8,IF(T15>=Reference!$B$7,Reference!$C$7,0)))+IF(U15>=Reference!$B$12,Reference!$C$12,IF(U15>=Reference!$B$11,Reference!$C$11,IF(U15>=Reference!$B$10,Reference!$C$10,0)))+IF(W15>=Reference!$B$13,Reference!$C$13,0)+IF(V15>=Reference!$B$15,Reference!$C$15,IF(V15>=Reference!$B$14,Reference!$C$14,0)))) -> 0 | Y15: =IF(X15="","",IF(X15>=Reference!$B$6,"HIGH",IF(X15>Reference!$B$5,"MODERATE","LOW"))) -> LOW
A16: 2 | B16: =INDEX(Participants!$B$6:$B$20,A16) -> Rishika Gupta | C16: 3 | D16: 0.34928241 | E16: Turning | F16: 3337 | G16: 1288 | H16: 444 | I16: -0.32 | J16: 0.18 | K16: 1.3 | L16: 37.3 | M16: 20.6 | N16: 27.1 | O16: 4.7 | P16: 9.6 | Q16: 118 | R16: 9 | S16: Y | T16: =IF(COUNT(I16:K16)<3,"",SQRT(I16^2+J16^2+K16^2)) -> 1.3508516 | U16: =IF(COUNT(L16:N16)<3,"",SQRT(L16^2+M16^2+N16^2)) -> 50.498119 | V16: =IF(COUNT(O16:P16)<2,"",SQRT(O16^2+P16^2)) -> 10.688779 | W16: =IF(T16="","",IF(T15="",0,ABS(T16-T15))) -> 0.21731729 | X16: =IF(OR(T16="",U16="",V16=""),"",MIN(100,IF(T16>=Reference!$B$9,Reference!$C$9,IF(T16>=Reference!$B$8,Reference!$C$8,IF(T16>=Reference!$B$7,Reference!$C$7,0)))+IF(U16>=Reference!$B$12,Reference!$C$12,IF(U16>=Reference!$B$11,Reference!$C$11,IF(U16>=Reference!$B$10,Reference!$C$10,0)))+IF(W16>=Reference!$B$13,Reference!$C$13,0)+IF(V16>=Reference!$B$15,Reference!$C$15,IF(V16>=Reference!$B$14,Reference!$C$14,0)))) -> 35 | Y16: =IF(X16="","",IF(X16>=Reference!$B$6,"HIGH",IF(X16>Reference!$B$5,"MODERATE","LOW"))) -> LOW
A17: 2 | B17: =INDEX(Participants!$B$6:$B$20,A17) -> Rishika Gupta | C17: 4 | D17: 0.34934028 | E17: Swing | F17: 129 | G17: 97 | H17: 63 | I17: 0.25 | J17: 0.24 | K17: 1.09 | L17: 22.2 | M17: 9.3 | N17: 15.9 | O17: -7.7 | P17: 3.1 | Q17: 147 | R17: 9 | S17: Y | T17: =IF(COUNT(I17:K17)<3,"",SQRT(I17^2+J17^2+K17^2)) -> 1.1437657 | U17: =IF(COUNT(L17:N17)<3,"",SQRT(L17^2+M17^2+N17^2)) -> 28.846837 | V17: =IF(COUNT(O17:P17)<2,"",SQRT(O17^2+P17^2)) -> 8.3006024 | W17: =IF(T17="","",IF(T16="",0,ABS(T17-T16))) -> 0.20708587 | X17: =IF(OR(T17="",U17="",V17=""),"",MIN(100,IF(T17>=Reference!$B$9,Reference!$C$9,IF(T17>=Reference!$B$8,Reference!$C$8,IF(T17>=Reference!$B$7,Reference!$C$7,0)))+IF(U17>=Reference!$B$12,Reference!$C$12,IF(U17>=Reference!$B$11,Reference!$C$11,IF(U17>=Reference!$B$10,Reference!$C$10,0)))+IF(W17>=Reference!$B$13,Reference!$C$13,0)+IF(V17>=Reference!$B$15,Reference!$C$15,IF(V17>=Reference!$B$14,Reference!$C$14,0)))) -> 13 | Y17: =IF(X17="","",IF(X17>=Reference!$B$6,"HIGH",IF(X17>Reference!$B$5,"MODERATE","LOW"))) -> LOW
A18: 2 | B18: =INDEX(Participants!$B$6:$B$20,A18) -> Rishika Gupta | C18: 5 | D18: 0.3494213 | E18: Turning | F18: 651 | G18: 735 | H18: 3892 | I18: 0.62 | J18: 0.34 | K18: 1.4 | L18: 40.1 | M18: 21.6 | N18: 37.2 | O18: 6.4 | P18: 8.3 | Q18: 93 | R18: 7 | S18: Y | T18: =IF(COUNT(I18:K18)<3,"",SQRT(I18^2+J18^2+K18^2)) -> 1.5684387 | U18: =IF(COUNT(L18:N18)<3,"",SQRT(L18^2+M18^2+N18^2)) -> 58.808248 | V18: =IF(COUNT(O18:P18)<2,"",SQRT(O18^2+P18^2)) -> 10.480935 | W18: =IF(T18="","",IF(T17="",0,ABS(T18-T17))) -> 0.424673 | X18: =IF(OR(T18="",U18="",V18=""),"",MIN(100,IF(T18>=Reference!$B$9,Reference!$C$9,IF(T18>=Reference!$B$8,Reference!$C$8,IF(T18>=Reference!$B$7,Reference!$C$7,0)))+IF(U18>=Reference!$B$12,Reference!$C$12,IF(U18>=Reference!$B$11,Reference!$C$11,IF(U18>=Reference!$B$10,Reference!$C$10,0)))+IF(W18>=Reference!$B$13,Reference!$C$13,0)+IF(V18>=Reference!$B$15,Reference!$C$15,IF(V18>=Reference!$B$14,Reference!$C$14,0)))) -> 65 | Y18: =IF(X18="","",IF(X18>=Reference!$B$6,"HIGH",IF(X18>Reference!$B$5,"MODERATE","LOW"))) -> MODERATE
A19: 2 | B19: =INDEX(Participants!$B$6:$B$20,A19) -> Rishika Gupta | C19: 6 | D19: 0.34950231 | E19: Foot flat | F19: 1534 | G19: 2230 | H19: 2541 | I19: 0.18 | J19: 0.08 | K19: 1.14 | L19: 9.7 | M19: 7.2 | N19: 5.4 | O19: 3.2 | P19: 1.7 | Q19: 148 | R19: 8 | S19: Y | T19: =IF(COUNT(I19:K19)<3,"",SQRT(I19^2+J19^2+K19^2)) -> 1.1568924 | U19: =IF(COUNT(L19:N19)<3,"",SQRT(L19^2+M19^2+N19^2)) -> 13.232158 | V19: =IF(COUNT(O19:P19)<2,"",SQRT(O19^2+P19^2)) -> 3.6235342 | W19: =IF(T19="","",IF(T18="",0,ABS(T19-T18))) -> 0.41154633 | X19: =IF(OR(T19="",U19="",V19=""),"",MIN(100,IF(T19>=Reference!$B$9,Reference!$C$9,IF(T19>=Reference!$B$8,Reference!$C$8,IF(T19>=Reference!$B$7,Reference!$C$7,0)))+IF(U19>=Reference!$B$12,Reference!$C$12,IF(U19>=Reference!$B$11,Reference!$C$11,IF(U19>=Reference!$B$10,Reference!$C$10,0)))+IF(W19>=Reference!$B$13,Reference!$C$13,0)+IF(V19>=Reference!$B$15,Reference!$C$15,IF(V19>=Reference!$B$14,Reference!$C$14,0)))) -> 15 | Y19: =IF(X19="","",IF(X19>=Reference!$B$6,"HIGH",IF(X19>Reference!$B$5,"MODERATE","LOW"))) -> LOW
A20: 2 | B20: =INDEX(Participants!$B$6:$B$20,A20) -> Rishika Gupta | C20: 7 | D20: 0.34953704 | E20: Toe off | F20: 3604 | G20: 1369 | H20: 401 | I20: 0.1 | J20: -0.06 | K20: 1.1 | L20: 9.1 | M20: 4.2 | N20: 2.8 | O20: -5.1 | P20: 2.4 | Q20: 172 | R20: 9 | S20: Y | T20: =IF(COUNT(I20:K20)<3,"",SQRT(I20^2+J20^2+K20^2)) -> 1.1061645 | U20: =IF(COUNT(L20:N20)<3,"",SQRT(L20^2+M20^2+N20^2)) -> 10.406248 | V20: =IF(COUNT(O20:P20)<2,"",SQRT(O20^2+P20^2)) -> 5.6364883 | W20: =IF(T20="","",IF(T19="",0,ABS(T20-T19))) -> 0.050727844 | X20: =IF(OR(T20="",U20="",V20=""),"",MIN(100,IF(T20>=Reference!$B$9,Reference!$C$9,IF(T20>=Reference!$B$8,Reference!$C$8,IF(T20>=Reference!$B$7,Reference!$C$7,0)))+IF(U20>=Reference!$B$12,Reference!$C$12,IF(U20>=Reference!$B$11,Reference!$C$11,IF(U20>=Reference!$B$10,Reference!$C$10,0)))+IF(W20>=Reference!$B$13,Reference!$C$13,0)+IF(V20>=Reference!$B$15,Reference!$C$15,IF(V20>=Reference!$B$14,Reference!$C$14,0)))) -> 0 | Y20: =IF(X20="","",IF(X20>=Reference!$B$6,"HIGH",IF(X20>Reference!$B$5,"MODERATE","LOW"))) -> LOW
A21: 2 | B21: =INDEX(Participants!$B$6:$B$20,A21) -> Rishika Gupta | C21: 8 | D21: 0.34960648 | E21: Heel strike | F21: 611 | G21: 864 | H21: 3312 | I21: 0.32 | J21: 0.17 | K21: 1.21 | L21: 22.8 | M21: 13.6 | N21: 16.1 | O21: 4.5 | P21: 2.8 | Q21: 112 | R21: 7 | S21: Y | T21: =IF(COUNT(I21:K21)<3,"",SQRT(I21^2+J21^2+K21^2)) -> 1.2630914 | U21: =IF(COUNT(L21:N21)<3,"",SQRT(L21^2+M21^2+N21^2)) -> 31.04851 | V21: =IF(COUNT(O21:P21)<2,"",SQRT(O21^2+P21^2)) -> 5.3 | W21: =IF(T21="","",IF(T20="",0,ABS(T21-T20))) -> 0.1569269 | X21: =IF(OR(T21="",U21="",V21=""),"",MIN(100,IF(T21>=Reference!$B$9,Reference!$C$9,IF(T21>=Reference!$B$8,Reference!$C$8,IF(T21>=Reference!$B$7,Reference!$C$7,0)))+IF(U21>=Reference!$B$12,Reference!$C$12,IF(U21>=Reference!$B$11,Reference!$C$11,IF(U21>=Reference!$B$10,Reference!$C$10,0)))+IF(W21>=Reference!$B$13,Reference!$C$13,0)+IF(V21>=Reference!$B$15,Reference!$C$15,IF(V21>=Reference!$B$14,Reference!$C$14,0)))) -> 20 | Y21: =IF(X21="","",IF(X21>=Reference!$B$6,"HIGH",IF(X21>Reference!$B$5,"MODERATE","LOW"))) -> LOW
A22: 3 | B22: =INDEX(Participants!$B$6:$B$20,A22) -> Vishav Gupta | C22: 1 | D22: 0.38402778 | E22: Heel strike | F22: 280 | G22: 439 | H22: 2551 | I22: 0.09 | J22: 0.05 | K22: 1.03 | L22: 4.6 | M22: 1.8 | N22: 2.2 | O22: 2.9 | P22: 1.1 | Q22: 237 | R22: 7 | S22: Y | T22: =IF(COUNT(I22:K22)<3,"",SQRT(I22^2+J22^2+K22^2)) -> 1.0351328 | U22: =IF(COUNT(L22:N22)<3,"",SQRT(L22^2+M22^2+N22^2)) -> 5.4074023 | V22: =IF(COUNT(O22:P22)<2,"",SQRT(O22^2+P22^2)) -> 3.1016125 | W22: =IF(T22="","",0) -> 0 | X22: =IF(OR(T22="",U22="",V22=""),"",MIN(100,IF(T22>=Reference!$B$9,Reference!$C$9,IF(T22>=Reference!$B$8,Reference!$C$8,IF(T22>=Reference!$B$7,Reference!$C$7,0)))+IF(U22>=Reference!$B$12,Reference!$C$12,IF(U22>=Reference!$B$11,Reference!$C$11,IF(U22>=Reference!$B$10,Reference!$C$10,0)))+IF(W22>=Reference!$B$13,Reference!$C$13,0)+IF(V22>=Reference!$B$15,Reference!$C$15,IF(V22>=Reference!$B$14,Reference!$C$14,0)))) -> 0 | Y22: =IF(X22="","",IF(X22>=Reference!$B$6,"HIGH",IF(X22>Reference!$B$5,"MODERATE","LOW"))) -> LOW
A23: 3 | B23: =INDEX(Participants!$B$6:$B$20,A23) -> Vishav Gupta | C23: 2 | D23: 0.38412037 | E23: Foot flat | F23: 971 | G23: 1559 | H23: 2183 | I23: 0.05 | J23: -0.03 | K23: 0.99 | L23: 1.9 | M23: 0.5 | N23: 1.1 | O23: 1.5 | P23: 0.8 | Q23: 211 | R23: 8 | S23: Y | T23: =IF(COUNT(I23:K23)<3,"",SQRT(I23^2+J23^2+K23^2)) -> 0.99171569 | U23: =IF(COUNT(L23:N23)<3,"",SQRT(L23^2+M23^2+N23^2)) -> 2.251666 | V23: =IF(COUNT(O23:P23)<2,"",SQRT(O23^2+P23^2)) -> 1.7 | W23: =IF(T23="","",IF(T22="",0,ABS(T23-T22))) -> 0.043417157 | X23: =IF(OR(T23="",U23="",V23=""),"",MIN(100,IF(T23>=Reference!$B$9,Reference!$C$9,IF(T23>=Reference!$B$8,Reference!$C$8,IF(T23>=Reference!$B$7,Reference!$C$7,0)))+IF(U23>=Reference!$B$12,Reference!$C$12,IF(U23>=Reference!$B$11,Reference!$C$11,IF(U23>=Reference!$B$10,Reference!$C$10,0)))+IF(W23>=Reference!$B$13,Reference!$C$13,0)+IF(V23>=Reference!$B$15,Reference!$C$15,IF(V23>=Reference!$B$14,Reference!$C$14,0)))) -> 0 | Y23: =IF(X23="","",IF(X23>=Reference!$B$6,"HIGH",IF(X23>Reference!$B$5,"MODERATE","LOW"))) -> LOW
A24: 3 | B24: =INDEX(Participants!$B$6:$B$20,A24) -> Vishav Gupta | C24: 3 | D24: 0.38418981 | E24: Mid stance | F24: 1905 | G24: 1830 | H24: 1191 | I24: 0.02 | J24: 0.05 | K24: 1.05 | L24: 1.7 | M24: -0.2 | N24: 0.1 | O24: 0.9 | P24: 0.5 | Q24: 176 | R24: 8 | S24: Y | T24: =IF(COUNT(I24:K24)<3,"",SQRT(I24^2+J24^2+K24^2)) -> 1.05138 | U24: =IF(COUNT(L24:N24)<3,"",SQRT(L24^2+M24^2+N24^2)) -> 1.7146428 | V24: =IF(COUNT(O24:P24)<2,"",SQRT(O24^2+P24^2)) -> 1.029563 | W24: =IF(T24="","",IF(T23="",0,ABS(T24-T23))) -> 0.05966436 | X24: =IF(OR(T24="",U24="",V24=""),"",MIN(100,IF(T24>=Reference!$B$9,Reference!$C$9,IF(T24>=Reference!$B$8,Reference!$C$8,IF(T24>=Reference!$B$7,Reference!$C$7,0)))+IF(U24>=Reference!$B$12,Reference!$C$12,IF(U24>=Reference!$B$11,Reference!$C$11,IF(U24>=Reference!$B$10,Reference!$C$10,0)))+IF(W24>=Reference!$B$13,Reference!$C$13,0)+IF(V24>=Reference!$B$15,Reference!$C$15,IF(V24>=Reference!$B$14,Reference!$C$14,0)))) -> 0 | Y24: =IF(X24="","",IF(X24>=Reference!$B$6,"HIGH",IF(X24>Reference!$B$5,"MODERATE","LOW"))) -> LOW
A25: 3 | B25: =INDEX(Participants!$B$6:$B$20,A25) -> Vishav Gupta | C25: 4 | D25: 0.38429398 | E25: Toe off | F25: 2893 | G25: 1090 | H25: 272 | I25: -0.13 | J25: 0.07 | K25: 1.11 | L25: 8.3 | M25: 3.4 | N25: 4.2 | O25: -6.1 | P25: 1.9 | Q25: 174 | R25: 7 | S25: Y | T25: =IF(COUNT(I25:K25)<3,"",SQRT(I25^2+J25^2+K25^2)) -> 1.1197768 | U25: =IF(COUNT(L25:N25)<3,"",SQRT(L25^2+M25^2+N25^2)) -> 9.9040396 | V25: =IF(COUNT(O25:P25)<2,"",SQRT(O25^2+P25^2)) -> 6.3890531 | W25: =IF(T25="","",IF(T24="",0,ABS(T25-T24))) -> 0.068396718 | X25: =IF(OR(T25="",U25="",V25=""),"",MIN(100,IF(T25>=Reference!$B$9,Reference!$C$9,IF(T25>=Reference!$B$8,Reference!$C$8,IF(T25>=Reference!$B$7,Reference!$C$7,0)))+IF(U25>=Reference!$B$12,Reference!$C$12,IF(U25>=Reference!$B$11,Reference!$C$11,IF(U25>=Reference!$B$10,Reference!$C$10,0)))+IF(W25>=Reference!$B$13,Reference!$C$13,0)+IF(V25>=Reference!$B$15,Reference!$C$15,IF(V25>=Reference!$B$14,Reference!$C$14,0)))) -> 0 | Y25: =IF(X25="","",IF(X25>=Reference!$B$6,"HIGH",IF(X25>Reference!$B$5,"MODERATE","LOW"))) -> LOW
A26: 3 | B26: =INDEX(Participants!$B$6:$B$20,A26) -> Vishav Gupta | C26: 5 | D26: 0.384375 | E26: Swing | F26: 101 | G26: 58 | H26: 45 | I26: 0.04 | J26: 0.05 | K26: 0.97 | L26: 16.5 | M26: 4.4 | N26: 6.4 | O26: -10.4 | P26: 2.3 | Q26: 169 | R26: 7 | S26: Y | T26: =IF(COUNT(I26:K26)<3,"",SQRT(I26^2+J26^2+K26^2)) -> 0.9721111 | U26: =IF(COUNT(L26:N26)<3,"",SQRT(L26^2+M26^2+N26^2)) -> 18.236502 | V26: =IF(COUNT(O26:P26)<2,"",SQRT(O26^2+P26^2)) -> 10.651291 | W26: =IF(T26="","",IF(T25="",0,ABS(T26-T25))) -> 0.14766566 | X26: =IF(OR(T26="",U26="",V26=""),"",MIN(100,IF(T26>=Reference!$B$9,Reference!$C$9,IF(T26>=Reference!$B$8,Reference!$C$8,IF(T26>=Reference!$B$7,Reference!$C$7,0)))+IF(U26>=Reference!$B$12,Reference!$C$12,IF(U26>=Reference!$B$11,Reference!$C$11,IF(U26>=Reference!$B$10,Reference!$C$10,0)))+IF(W26>=Reference!$B$13,Reference!$C$13,0)+IF(V26>=Reference!$B$15,Reference!$C$15,IF(V26>=Reference!$B$14,Reference!$C$14,0)))) -> 5 | Y26: =IF(X26="","",IF(X26>=Reference!$B$6,"HIGH",IF(X26>Reference!$B$5,"MODERATE","LOW"))) -> LOW
A27: 3 | B27: =INDEX(Participants!$B$6:$B$20,A27) -> Vishav Gupta | C27: 6 | D27: 0.38446759 | E27: Heel strike | F27: 311 | G27: 514 | H27: 2699 | I27: 0.09 | J27: 0.06 | K27: 1.04 | L27: 5.3 | M27: 2.1 | N27: 2.4 | O27: 3.5 | P27: 1.2 | Q27: 230 | R27: 8 | S27: Y | T27: =IF(COUNT(I27:K27)<3,"",SQRT(I27^2+J27^2+K27^2)) -> 1.0456099 | U27: =IF(COUNT(L27:N27)<3,"",SQRT(L27^2+M27^2+N27^2)) -> 6.1854668 | V27: =IF(COUNT(O27:P27)<2,"",SQRT(O27^2+P27^2)) -> 3.7 | W27: =IF(T27="","",IF(T26="",0,ABS(T27-T26))) -> 0.073498765 | X27: =IF(OR(T27="",U27="",V27=""),"",MIN(100,IF(T27>=Reference!$B$9,Reference!$C$9,IF(T27>=Reference!$B$8,Reference!$C$8,IF(T27>=Reference!$B$7,Reference!$C$7,0)))+IF(U27>=Reference!$B$12,Reference!$C$12,IF(U27>=Reference!$B$11,Reference!$C$11,IF(U27>=Reference!$B$10,Reference!$C$10,0)))+IF(W27>=Reference!$B$13,Reference!$C$13,0)+IF(V27>=Reference!$B$15,Reference!$C$15,IF(V27>=Reference!$B$14,Reference!$C$14,0)))) -> 0 | Y27: =IF(X27="","",IF(X27>=Reference!$B$6,"HIGH",IF(X27>Reference!$B$5,"MODERATE","LOW"))) -> LOW
A28: 3 | B28: =INDEX(Participants!$B$6:$B$20,A28) -> Vishav Gupta | C28: 7 | D28: 0.38452546 | E28: Foot flat | F28: 1052 | G28: 1570 | H28: 2202 | I28: 0.01 | J28: -0.01 | K28: 1 | L28: 2.4 | M28: 1.2 | N28: 0.6 | O28: 1.2 | P28: 0.6 | Q28: 227 | R28: 7 | S28: Y | T28: =IF(COUNT(I28:K28)<3,"",SQRT(I28^2+J28^2+K28^2)) -> 1.0001 | U28: =IF(COUNT(L28:N28)<3,"",SQRT(L28^2+M28^2+N28^2)) -> 2.7495454 | V28: =IF(COUNT(O28:P28)<2,"",SQRT(O28^2+P28^2)) -> 1.3416408 | W28: =IF(T28="","",IF(T27="",0,ABS(T28-T27))) -> 0.045509875 | X28: =IF(OR(T28="",U28="",V28=""),"",MIN(100,IF(T28>=Reference!$B$9,Reference!$C$9,IF(T28>=Reference!$B$8,Reference!$C$8,IF(T28>=Reference!$B$7,Reference!$C$7,0)))+IF(U28>=Reference!$B$12,Reference!$C$12,IF(U28>=Reference!$B$11,Reference!$C$11,IF(U28>=Reference!$B$10,Reference!$C$10,0)))+IF(W28>=Reference!$B$13,Reference!$C$13,0)+IF(V28>=Reference!$B$15,Reference!$C$15,IF(V28>=Reference!$B$14,Reference!$C$14,0)))) -> 0 | Y28: =IF(X28="","",IF(X28>=Reference!$B$6,"HIGH",IF(X28>Reference!$B$5,"MODERATE","LOW"))) -> LOW
A29: 3 | B29: =INDEX(Participants!$B$6:$B$20,A29) -> Vishav Gupta | C29: 8 | D29: 0.3846412 | E29: Toe off | F29: 3128 | G29: 1008 | H29: 239 | I29: -0.1 | J29: 0.05 | K29: 1.08 | L29: 10.4 | M29: 3.5 | N29: 4.6 | O29: -6.8 | P29: 1.8 | Q29: 210 | R29: 7 | S29: Y | T29: =IF(COUNT(I29:K29)<3,"",SQRT(I29^2+J29^2+K29^2)) -> 1.0857716 | U29: =IF(COUNT(L29:N29)<3,"",SQRT(L29^2+M29^2+N29^2)) -> 11.898319 | V29: =IF(COUNT(O29:P29)<2,"",SQRT(O29^2+P29^2)) -> 7.0342022 | W29: =IF(T29="","",IF(T28="",0,ABS(T29-T28))) -> 0.08567162 | X29: =IF(OR(T29="",U29="",V29=""),"",MIN(100,IF(T29>=Reference!$B$9,Reference!$C$9,IF(T29>=Reference!$B$8,Reference!$C$8,IF(T29>=Reference!$B$7,Reference!$C$7,0)))+IF(U29>=Reference!$B$12,Reference!$C$12,IF(U29>=Reference!$B$11,Reference!$C$11,IF(U29>=Reference!$B$10,Reference!$C$10,0)))+IF(W29>=Reference!$B$13,Reference!$C$13,0)+IF(V29>=Reference!$B$15,Reference!$C$15,IF(V29>=Reference!$B$14,Reference!$C$14,0)))) -> 0 | Y29: =IF(X29="","",IF(X29>=Reference!$B$6,"HIGH",IF(X29>Reference!$B$5,"MODERATE","LOW"))) -> LOW
A30: 4 | B30: =INDEX(Participants!$B$6:$B$20,A30) -> Vedant Singh | C30: 1 | D30: 0.40971065 | E30: Standing | F30: 994 | G30: 820 | H30: 1557 | I30: 0 | J30: 0.02 | K30: 0.98 | L30: 1 | M30: 0.3 | N30: 0.4 | O30: 0.8 | P30: 0.4 | Q30: 302 | R30: 3 | S30: N | T30: =IF(COUNT(I30:K30)<3,"",SQRT(I30^2+J30^2+K30^2)) -> 0.98020406 | U30: =IF(COUNT(L30:N30)<3,"",SQRT(L30^2+M30^2+N30^2)) -> 1.118034 | V30: =IF(COUNT(O30:P30)<2,"",SQRT(O30^2+P30^2)) -> 0.89442719 | W30: =IF(T30="","",0) -> 0 | X30: =IF(OR(T30="",U30="",V30=""),"",MIN(100,IF(T30>=Reference!$B$9,Reference!$C$9,IF(T30>=Reference!$B$8,Reference!$C$8,IF(T30>=Reference!$B$7,Reference!$C$7,0)))+IF(U30>=Reference!$B$12,Reference!$C$12,IF(U30>=Reference!$B$11,Reference!$C$11,IF(U30>=Reference!$B$10,Reference!$C$10,0)))+IF(W30>=Reference!$B$13,Reference!$C$13,0)+IF(V30>=Reference!$B$15,Reference!$C$15,IF(V30>=Reference!$B$14,Reference!$C$14,0)))) -> 0 | Y30: =IF(X30="","",IF(X30>=Reference!$B$6,"HIGH",IF(X30>Reference!$B$5,"MODERATE","LOW"))) -> LOW
A31: 4 | B31: =INDEX(Participants!$B$6:$B$20,A31) -> Vedant Singh | C31: 2 | D31: 0.40983796 | E31: Standing | F31: 1148 | G31: 969 | H31: 1692 | I31: 0.01 | J31: 0.02 | K31: 0.98 | L31: 0.8 | M31: 1 | N31: 0.5 | O31: 1.1 | P31: 0.7 | Q31: 349 | R31: 3 | S31: N | T31: =IF(COUNT(I31:K31)<3,"",SQRT(I31^2+J31^2+K31^2)) -> 0.98025507 | U31: =IF(COUNT(L31:N31)<3,"",SQRT(L31^2+M31^2+N31^2)) -> 1.3747727 | V31: =IF(COUNT(O31:P31)<2,"",SQRT(O31^2+P31^2)) -> 1.3038405 | W31: =IF(T31="","",IF(T30="",0,ABS(T31-T30))) -> 5.1008459e-05 | X31: =IF(OR(T31="",U31="",V31=""),"",MIN(100,IF(T31>=Reference!$B$9,Reference!$C$9,IF(T31>=Reference!$B$8,Reference!$C$8,IF(T31>=Reference!$B$7,Reference!$C$7,0)))+IF(U31>=Reference!$B$12,Reference!$C$12,IF(U31>=Reference!$B$11,Reference!$C$11,IF(U31>=Reference!$B$10,Reference!$C$10,0)))+IF(W31>=Reference!$B$13,Reference!$C$13,0)+IF(V31>=Reference!$B$15,Reference!$C$15,IF(V31>=Reference!$B$14,Reference!$C$14,0)))) -> 0 | Y31: =IF(X31="","",IF(X31>=Reference!$B$6,"HIGH",IF(X31>Reference!$B$5,"MODERATE","LOW"))) -> LOW
A32: 4 | B32: =INDEX(Participants!$B$6:$B$20,A32) -> Vedant Singh | C32: 3 | D32: 0.4099537 | E32: Standing | F32: 1161 | G32: 953 | H32: 1804 | I32: 0.01 | J32: 0.02 | K32: 1 | L32: 0.3 | M32: 0.5 | N32: 0.4 | O32: 0.8 | P32: 0.3 | Q32: 299 | R32: 3 | S32: N | T32: =IF(COUNT(I32:K32)<3,"",SQRT(I32^2+J32^2+K32^2)) -> 1.00025 | U32: =IF(COUNT(L32:N32)<3,"",SQRT(L32^2+M32^2+N32^2)) -> 0.70710678 | V32: =IF(COUNT(O32:P32)<2,"",SQRT(O32^2+P32^2)) -> 0.85440037 | W32: =IF(T32="","",IF(T31="",0,ABS(T32-T31))) -> 0.0199949 | X32: =IF(OR(T32="",U32="",V32=""),"",MIN(100,IF(T32>=Reference!$B$9,Reference!$C$9,IF(T32>=Reference!$B$8,Reference!$C$8,IF(T32>=Reference!$B$7,Reference!$C$7,0)))+IF(U32>=Reference!$B$12,Reference!$C$12,IF(U32>=Reference!$B$11,Reference!$C$11,IF(U32>=Reference!$B$10,Reference!$C$10,0)))+IF(W32>=Reference!$B$13,Reference!$C$13,0)+IF(V32>=Reference!$B$15,Reference!$C$15,IF(V32>=Reference!$B$14,Reference!$C$14,0)))) -> 0 | Y32: =IF(X32="","",IF(X32>=Reference!$B$6,"HIGH",IF(X32>Reference!$B$5,"MODERATE","LOW"))) -> LOW
A33: 4 | B33: =INDEX(Participants!$B$6:$B$20,A33) -> Vedant Singh | C33: 4 | D33: 0.41012731 | E33: Weight shift | F33: 1316 | G33: 937 | H33: 1612 | I33: 0.04 | J33: 0.04 | K33: 1 | L33: 2.3 | M33: 1 | N33: 1.2 | O33: 1.8 | P33: 0.9 | Q33: 307 | R33: 3 | S33: N | T33: =IF(COUNT(I33:K33)<3,"",SQRT(I33^2+J33^2+K33^2)) -> 1.0015987 | U33: =IF(COUNT(L33:N33)<3,"",SQRT(L33^2+M33^2+N33^2)) -> 2.7802878 | V33: =IF(COUNT(O33:P33)<2,"",SQRT(O33^2+P33^2)) -> 2.0124612 | W33: =IF(T33="","",IF(T32="",0,ABS(T33-T32))) -> 0.0013487533 | X33: =IF(OR(T33="",U33="",V33=""),"",MIN(100,IF(T33>=Reference!$B$9,Reference!$C$9,IF(T33>=Reference!$B$8,Reference!$C$8,IF(T33>=Reference!$B$7,Reference!$C$7,0)))+IF(U33>=Reference!$B$12,Reference!$C$12,IF(U33>=Reference!$B$11,Reference!$C$11,IF(U33>=Reference!$B$10,Reference!$C$10,0)))+IF(W33>=Reference!$B$13,Reference!$C$13,0)+IF(V33>=Reference!$B$15,Reference!$C$15,IF(V33>=Reference!$B$14,Reference!$C$14,0)))) -> 0 | Y33: =IF(X33="","",IF(X33>=Reference!$B$6,"HIGH",IF(X33>Reference!$B$5,"MODERATE","LOW"))) -> LOW
A34: 4 | B34: =INDEX(Participants!$B$6:$B$20,A34) -> Vedant Singh | C34: 5 | D34: 0.41024306 | E34: Standing | F34: 1270 | G34: 842 | H34: 1740 | I34: 0.01 | J34: 0.04 | K34: 0.98 | L34: 0.2 | M34: 0.7 | N34: 0.1 | O34: 1 | P34: 0.4 | Q34: 288 | R34: 3 | S34: N | T34: =IF(COUNT(I34:K34)<3,"",SQRT(I34^2+J34^2+K34^2)) -> 0.98086696 | U34: =IF(COUNT(L34:N34)<3,"",SQRT(L34^2+M34^2+N34^2)) -> 0.73484692 | V34: =IF(COUNT(O34:P34)<2,"",SQRT(O34^2+P34^2)) -> 1.077033 | W34: =IF(T34="","",IF(T33="",0,ABS(T34-T33))) -> 0.020731759 | X34: =IF(OR(T34="",U34="",V34=""),"",MIN(100,IF(T34>=Reference!$B$9,Reference!$C$9,IF(T34>=Reference!$B$8,Reference!$C$8,IF(T34>=Reference!$B$7,Reference!$C$7,0)))+IF(U34>=Reference!$B$12,Reference!$C$12,IF(U34>=Reference!$B$11,Reference!$C$11,IF(U34>=Reference!$B$10,Reference!$C$10,0)))+IF(W34>=Reference!$B$13,Reference!$C$13,0)+IF(V34>=Reference!$B$15,Reference!$C$15,IF(V34>=Reference!$B$14,Reference!$C$14,0)))) -> 0 | Y34: =IF(X34="","",IF(X34>=Reference!$B$6,"HIGH",IF(X34>Reference!$B$5,"MODERATE","LOW"))) -> LOW
A35: 4 | B35: =INDEX(Participants!$B$6:$B$20,A35) -> Vedant Singh | C35: 6 | D35: 0.41033565 | E35: Weight shift | F35: 1423 | G35: 1098 | H35: 1618 | I35: 0.05 | J35: 0.03 | K35: 0.99 | L35: 2.2 | M35: 1.9 | N35: 1.2 | O35: 1.9 | P35: 1 | Q35: 316 | R35: 3 | S35: N | T35: =IF(COUNT(I35:K35)<3,"",SQRT(I35^2+J35^2+K35^2)) -> 0.99171569 | U35: =IF(COUNT(L35:N35)<3,"",SQRT(L35^2+M35^2+N35^2)) -> 3.144837 | V35: =IF(COUNT(O35:P35)<2,"",SQRT(O35^2+P35^2)) -> 2.1470911 | W35: =IF(T35="","",IF(T34="",0,ABS(T35-T34))) -> 0.010848722 | X35: =IF(OR(T35="",U35="",V35=""),"",MIN(100,IF(T35>=Reference!$B$9,Reference!$C$9,IF(T35>=Reference!$B$8,Reference!$C$8,IF(T35>=Reference!$B$7,Reference!$C$7,0)))+IF(U35>=Reference!$B$12,Reference!$C$12,IF(U35>=Reference!$B$11,Reference!$C$11,IF(U35>=Reference!$B$10,Reference!$C$10,0)))+IF(W35>=Reference!$B$13,Reference!$C$13,0)+IF(V35>=Reference!$B$15,Reference!$C$15,IF(V35>=Reference!$B$14,Reference!$C$14,0)))) -> 0 | Y35: =IF(X35="","",IF(X35>=Reference!$B$6,"HIGH",IF(X35>Reference!$B$5,"MODERATE","LOW"))) -> LOW
A36: 4 | B36: =INDEX(Participants!$B$6:$B$20,A36) -> Vedant Singh | C36: 7 | D36: 0.41049769 | E36: Standing | F36: 1143 | G36: 799 | H36: 1614 | I36: 0.02 | J36: 0 | K36: 1 | L36: 0.2 | M36: 0.1 | N36: 1 | O36: 0.8 | P36: 0.5 | Q36: 324 | R36: 3 | S36: N | T36: =IF(COUNT(I36:K36)<3,"",SQRT(I36^2+J36^2+K36^2)) -> 1.0002 | U36: =IF(COUNT(L36:N36)<3,"",SQRT(L36^2+M36^2+N36^2)) -> 1.0246951 | V36: =IF(COUNT(O36:P36)<2,"",SQRT(O36^2+P36^2)) -> 0.94339811 | W36: =IF(T36="","",IF(T35="",0,ABS(T36-T35))) -> 0.0084842949 | X36: =IF(OR(T36="",U36="",V36=""),"",MIN(100,IF(T36>=Reference!$B$9,Reference!$C$9,IF(T36>=Reference!$B$8,Reference!$C$8,IF(T36>=Reference!$B$7,Reference!$C$7,0)))+IF(U36>=Reference!$B$12,Reference!$C$12,IF(U36>=Reference!$B$11,Reference!$C$11,IF(U36>=Reference!$B$10,Reference!$C$10,0)))+IF(W36>=Reference!$B$13,Reference!$C$13,0)+IF(V36>=Reference!$B$15,Reference!$C$15,IF(V36>=Reference!$B$14,Reference!$C$14,0)))) -> 0 | Y36: =IF(X36="","",IF(X36>=Reference!$B$6,"HIGH",IF(X36>Reference!$B$5,"MODERATE","LOW"))) -> LOW
A37: 4 | B37: =INDEX(Participants!$B$6:$B$20,A37) -> Vedant Singh | C37: 8 | D37: 0.410625 | E37: Standing | F37: 1132 | G37: 884 | H37: 1712 | I37: 0 | J37: 0.03 | K37: 1.02 | L37: 1.4 | M37: 0.3 | N37: 0.5 | O37: 1.1 | P37: 0.4 | Q37: 353 | R37: 3 | S37: N | T37: =IF(COUNT(I37:K37)<3,"",SQRT(I37^2+J37^2+K37^2)) -> 1.0204411 | U37: =IF(COUNT(L37:N37)<3,"",SQRT(L37^2+M37^2+N37^2)) -> 1.5165751 | V37: =IF(COUNT(O37:P37)<2,"",SQRT(O37^2+P37^2)) -> 1.17047 | W37: =IF(T37="","",IF(T36="",0,ABS(T37-T36))) -> 0.020241101 | X37: =IF(OR(T37="",U37="",V37=""),"",MIN(100,IF(T37>=Reference!$B$9,Reference!$C$9,IF(T37>=Reference!$B$8,Reference!$C$8,IF(T37>=Reference!$B$7,Reference!$C$7,0)))+IF(U37>=Reference!$B$12,Reference!$C$12,IF(U37>=Reference!$B$11,Reference!$C$11,IF(U37>=Reference!$B$10,Reference!$C$10,0)))+IF(W37>=Reference!$B$13,Reference!$C$13,0)+IF(V37>=Reference!$B$15,Reference!$C$15,IF(V37>=Reference!$B$14,Reference!$C$14,0)))) -> 0 | Y37: =IF(X37="","",IF(X37>=Reference!$B$6,"HIGH",IF(X37>Reference!$B$5,"MODERATE","LOW"))) -> LOW
A38: 5 | B38: =INDEX(Participants!$B$6:$B$20,A38) -> Daksh Jain | C38: 1 | D38: 0.4012963 | E38: Walking | F38: 634 | G38: 769 | H38: 3220 | I38: 0.08 | J38: 0.04 | K38: 1.03 | L38: 6 | M38: 3.3 | N38: 4 | O38: 2.8 | P38: 1.1 | Q38: 116 | R38: 6 | S38: Y | T38: =IF(COUNT(I38:K38)<3,"",SQRT(I38^2+J38^2+K38^2)) -> 1.0338762 | U38: =IF(COUNT(L38:N38)<3,"",SQRT(L38^2+M38^2+N38^2)) -> 7.9303216 | V38: =IF(COUNT(O38:P38)<2,"",SQRT(O38^2+P38^2)) -> 3.0083218 | W38: =IF(T38="","",0) -> 0 | X38: =IF(OR(T38="",U38="",V38=""),"",MIN(100,IF(T38>=Reference!$B$9,Reference!$C$9,IF(T38>=Reference!$B$8,Reference!$C$8,IF(T38>=Reference!$B$7,Reference!$C$7,0)))+IF(U38>=Reference!$B$12,Reference!$C$12,IF(U38>=Reference!$B$11,Reference!$C$11,IF(U38>=Reference!$B$10,Reference!$C$10,0)))+IF(W38>=Reference!$B$13,Reference!$C$13,0)+IF(V38>=Reference!$B$15,Reference!$C$15,IF(V38>=Reference!$B$14,Reference!$C$14,0)))) -> 0 | Y38: =IF(X38="","",IF(X38>=Reference!$B$6,"HIGH",IF(X38>Reference!$B$5,"MODERATE","LOW"))) -> LOW
A39: 5 | B39: =INDEX(Participants!$B$6:$B$20,A39) -> Daksh Jain | C39: 2 | D39: 0.40136574 | E39: Walking | F39: 1487 | G39: 1850 | H39: 2423 | I39: 0.12 | J39: 0.08 | K39: 1.06 | L39: 9.1 | M39: 4.9 | N39: 6 | O39: 3.4 | P39: 1.5 | Q39: 102 | R39: 5 | S39: Y | T39: =IF(COUNT(I39:K39)<3,"",SQRT(I39^2+J39^2+K39^2)) -> 1.0697663 | U39: =IF(COUNT(L39:N39)<3,"",SQRT(L39^2+M39^2+N39^2)) -> 11.950732 | V39: =IF(COUNT(O39:P39)<2,"",SQRT(O39^2+P39^2)) -> 3.7161808 | W39: =IF(T39="","",IF(T38="",0,ABS(T39-T38))) -> 0.035890128 | X39: =IF(OR(T39="",U39="",V39=""),"",MIN(100,IF(T39>=Reference!$B$9,Reference!$C$9,IF(T39>=Reference!$B$8,Reference!$C$8,IF(T39>=Reference!$B$7,Reference!$C$7,0)))+IF(U39>=Reference!$B$12,Reference!$C$12,IF(U39>=Reference!$B$11,Reference!$C$11,IF(U39>=Reference!$B$10,Reference!$C$10,0)))+IF(W39>=Reference!$B$13,Reference!$C$13,0)+IF(V39>=Reference!$B$15,Reference!$C$15,IF(V39>=Reference!$B$14,Reference!$C$14,0)))) -> 0 | Y39: =IF(X39="","",IF(X39>=Reference!$B$6,"HIGH",IF(X39>Reference!$B$5,"MODERATE","LOW"))) -> LOW
A40: 5 | B40: =INDEX(Participants!$B$6:$B$20,A40) -> Daksh Jain | C40: 3 | D40: 0.40143519 | E40: Trip begins | F40: 4084 | G40: 1221 | H40: 119 | I40: 0.88 | J40: 0.43 | K40: 1.62 | L40: 45.9 | M40: 27.3 | N40: 38.9 | O40: 13.8 | P40: 9.2 | Q40: 63 | R40: 5 | S40: Y | T40: =IF(COUNT(I40:K40)<3,"",SQRT(I40^2+J40^2+K40^2)) -> 1.8930663 | U40: =IF(COUNT(L40:N40)<3,"",SQRT(L40^2+M40^2+N40^2)) -> 66.070493 | V40: =IF(COUNT(O40:P40)<2,"",SQRT(O40^2+P40^2)) -> 16.585536 | W40: =IF(T40="","",IF(T39="",0,ABS(T40-T39))) -> 0.82329997 | X40: =IF(OR(T40="",U40="",V40=""),"",MIN(100,IF(T40>=Reference!$B$9,Reference!$C$9,IF(T40>=Reference!$B$8,Reference!$C$8,IF(T40>=Reference!$B$7,Reference!$C$7,0)))+IF(U40>=Reference!$B$12,Reference!$C$12,IF(U40>=Reference!$B$11,Reference!$C$11,IF(U40>=Reference!$B$10,Reference!$C$10,0)))+IF(W40>=Reference!$B$13,Reference!$C$13,0)+IF(V40>=Reference!$B$15,Reference!$C$15,IF(V40>=Reference!$B$14,Reference!$C$14,0)))) -> 70 | Y40: =IF(X40="","",IF(X40>=Reference!$B$6,"HIGH",IF(X40>Reference!$B$5,"MODERATE","LOW"))) -> HIGH
A41: 5 | B41: =INDEX(Participants!$B$6:$B$20,A41) -> Daksh Jain | C41: 4 | D41: 0.4015162 | E41: Stumble peak | F41: 3684 | G41: 2717 | H41: 374 | I41: 1.63 | J41: -0.95 | K41: 2.31 | L41: 90 | M41: 60.6 | N41: 72.9 | O41: 21 | P41: 12 | Q41: 39 | R41: 5 | S41: Y | T41: =IF(COUNT(I41:K41)<3,"",SQRT(I41^2+J41^2+K41^2)) -> 2.9825325 | U41: =IF(COUNT(L41:N41)<3,"",SQRT(L41^2+M41^2+N41^2)) -> 130.71637 | V41: =IF(COUNT(O41:P41)<2,"",SQRT(O41^2+P41^2)) -> 24.186773 | W41: =IF(T41="","",IF(T40="",0,ABS(T41-T40))) -> 1.0894662 | X41: =IF(OR(T41="",U41="",V41=""),"",MIN(100,IF(T41>=Reference!$B$9,Reference!$C$9,IF(T41>=Reference!$B$8,Reference!$C$8,IF(T41>=Reference!$B$7,Reference!$C$7,0)))+IF(U41>=Reference!$B$12,Reference!$C$12,IF(U41>=Reference!$B$11,Reference!$C$11,IF(U41>=Reference!$B$10,Reference!$C$10,0)))+IF(W41>=Reference!$B$13,Reference!$C$13,0)+IF(V41>=Reference!$B$15,Reference!$C$15,IF(V41>=Reference!$B$14,Reference!$C$14,0)))) -> 100 | Y41: =IF(X41="","",IF(X41>=Reference!$B$6,"HIGH",IF(X41>Reference!$B$5,"MODERATE","LOW"))) -> HIGH
...

Sheet Summary
A1: Summary - one line per person
A5: # | B5: Name | C5: Height (cm) | D5: Weight (kg) | E5: BMI | F5: Readings logged | G5: Peak risk score | H5: Mean risk score | I5: Highest level | J5: Closest obstacle (cm) | K5: Peak accel (g) | L5: Peak gyro (deg/s)
A6: 1 | B6: =Participants!B6 -> Vidula Nijhawan | C6: =IF(Participants!E6="","",Participants!E6) -> 160 | D6: =IF(Participants!F6="","",Participants!F6) -> 52 | E6: =IF(Participants!G6="","",Participants!G6) -> 20.3125 | F6: =COUNT(Readings!X6:X13) -> 8 | G6: =IF(F6=0,"",MAX(Readings!X6:X13)) -> 5 | H6: =IF(F6=0,"",ROUND(AVERAGE(Readings!X6:X13),0)) -> 1 | I6: =IF(G6="","",IF(G6>=Reference!$B$6,"HIGH",IF(G6>Reference!$B$5,"MODERATE","LOW"))) -> LOW | J6: =IF(COUNT(Readings!Q6:Q13)=0,"",MIN(Readings!Q6:Q13)) -> 177 | K6: =IF(COUNT(Readings!T6:T13)=0,"",MAX(Readings!T6:T13)) -> 1.1183023 | L6: =IF(COUNT(Readings!U6:U13)=0,"",MAX(Readings!U6:U13)) -> 15.554742
A7: 2 | B7: =Participants!B7 -> Rishika Gupta | C7: =IF(Participants!E7="","",Participants!E7) -> 163 | D7: =IF(Participants!F7="","",Participants!F7) -> 55 | E7: =IF(Participants!G7="","",Participants!G7) -> 20.700817 | F7: =COUNT(Readings!X14:X21) -> 8 | G7: =IF(F7=0,"",MAX(Readings!X14:X21)) -> 65 | H7: =IF(F7=0,"",ROUND(AVERAGE(Readings!X14:X21),0)) -> 20 | I7: =IF(G7="","",IF(G7>=Reference!$B$6,"HIGH",IF(G7>Reference!$B$5,"MODERATE","LOW"))) -> MODERATE | J7: =IF(COUNT(Readings!Q14:Q21)=0,"",MIN(Readings!Q14:Q21)) -> 93 | K7: =IF(COUNT(Readings!T14:T21)=0,"",MAX(Readings!T14:T21)) -> 1.5684387 | L7: =IF(COUNT(Readings!U14:U21)=0,"",MAX(Readings!U14:U21)) -> 58.808248
A8: 3 | B8: =Participants!B8 -> Vishav Gupta | C8: =IF(Participants!E8="","",Participants!E8) -> 174 | D8: =IF(Participants!F8="","",Participants!F8) -> 68 | E8: =IF(Participants!G8="","",Participants!G8) -> 22.460034 | F8: =COUNT(Readings!X22:X29) -> 8 | G8: =IF(F8=0,"",MAX(Readings!X22:X29)) -> 5 | H8: =IF(F8=0,"",ROUND(AVERAGE(Readings!X22:X29),0)) -> 1 | I8: =IF(G8="","",IF(G8>=Reference!$B$6,"HIGH",IF(G8>Reference!$B$5,"MODERATE","LOW"))) -> LOW | J8: =IF(COUNT(Readings!Q22:Q29)=0,"",MIN(Readings!Q22:Q29)) -> 169 | K8: =IF(COUNT(Readings!T22:T29)=0,"",MAX(Readings!T22:T29)) -> 1.1197768 | L8: =IF(COUNT(Readings!U22:U29)=0,"",MAX(Readings!U22:U29)) -> 18.236502
A9: 4 | B9: =Participants!B9 -> Vedant Singh | C9: =IF(Participants!E9="","",Participants!E9) -> 178 | D9: =IF(Participants!F9="","",Participants!F9) -> 72 | E9: =IF(Participants!G9="","",Participants!G9) -> 22.724403 | F9: =COUNT(Readings!X30:X37) -> 8 | G9: =IF(F9=0,"",MAX(Readings!X30:X37)) -> 0 | H9: =IF(F9=0,"",ROUND(AVERAGE(Readings!X30:X37),0)) -> 0 | I9: =IF(G9="","",IF(G9>=Reference!$B$6,"HIGH",IF(G9>Reference!$B$5,"MODERATE","LOW"))) -> LOW | J9: =IF(COUNT(Readings!Q30:Q37)=0,"",MIN(Readings!Q30:Q37)) -> 288 | K9: =IF(COUNT(Readings!T30:T37)=0,"",MAX(Readings!T30:T37)) -> 1.0204411 | L9: =IF(COUNT(Readings!U30:U37)=0,"",MAX(Readings!U30:U37)) -> 3.144837
A10: 5 | B10: =Participants!B10 -> Daksh Jain | C10: =IF(Participants!E10="","",Participants!E10) -> 172 | D10: =IF(Participants!F10="","",Participants!F10) -> 64 | E10: =IF(Participants!G10="","",Participants!G10) -> 21.633315 | F10: =COUNT(Readings!X38:X45) -> 8 | G10: =IF(F10=0,"",MAX(Readings!X38:X45)) -> 100 | H10: =IF(F10=0,"",ROUND(AVERAGE(Readings!X38:X45),0)) -> 29 | I10: =IF(G10="","",IF(G10>=Reference!$B$6,"HIGH",IF(G10>Reference!$B$5,"MODERATE","LOW"))) -> HIGH | J10: =IF(COUNT(Readings!Q38:Q45)=0,"",MIN(Readings!Q38:Q45)) -> 39 | K10: =IF(COUNT(Readings!T38:T45)=0,"",MAX(Readings!T38:T45)) -> 2.9825325 | L10: =IF(COUNT(Readings!U38:U45)=0,"",MAX(Readings!U38:U45)) -> 130.71637
A11: 6 | B11: =Participants!B11 -> Sudeep | C11: =IF(Participants!E11="","",Participants!E11) -> 176 | D11: =IF(Participants!F11="","",Participants!F11) -> 70 | E11: =IF(Participants!G11="","",Participants!G11) -> 22.59814 | F11: =COUNT(Readings!X46:X53) -> 8 | G11: =IF(F11=0,"",MAX(Readings!X46:X53)) -> 5 | H11: =IF(F11=0,"",ROUND(AVERAGE(Readings!X46:X53),0)) -> 1 | I11: =IF(G11="","",IF(G11>=Reference!$B$6,"HIGH",IF(G11>Reference!$B$5,"MODERATE","LOW"))) -> LOW | J11: =IF(COUNT(Readings!Q46:Q53)=0,"",MIN(Readings!Q46:Q53)) -> 168 | K11: =IF(COUNT(Readings!T46:T53)=0,"",MAX(Readings!T46:T53)) -> 1.148956 | L11: =IF(COUNT(Readings!U46:U53)=0,"",MAX(Readings!U46:U53)) -> 16.530275
A12: 7 | B12: =Participants!B12 -> Dhairya | C12: =IF(Participants!E12="","",Participants!E12) -> 170 | D12: =IF(Participants!F12="","",Participants!F12) -> 62 | E12: =IF(Participants!G12="","",Participants!G12) -> 21.453287 | F12: =COUNT(Readings!X54:X61) -> 8 | G12: =IF(F12=0,"",MAX(Readings!X54:X61)) -> 65 | H12: =IF(F12=0,"",ROUND(AVERAGE(Readings!X54:X61),0)) -> 17 | I12: =IF(G12="","",IF(G12>=Reference!$B$6,"HIGH",IF(G12>Reference!$B$5,"MODERATE","LOW"))) -> MODERATE | J12: =IF(COUNT(Readings!Q54:Q61)=0,"",MIN(Readings!Q54:Q61)) -> 88 | K12: =IF(COUNT(Readings!T54:T61)=0,"",MAX(Readings!T54:T61)) -> 1.5728954 | L12: =IF(COUNT(Readings!U54:U61)=0,"",MAX(Readings!U54:U61)) -> 53.81654
A13: 8 | B13: =Participants!B13 -> Sanjana | C13: =IF(Participants!E13="","",Participants!E13) -> 158 | D13: =IF(Participants!F13="","",Participants!F13) -> 50 | E13: =IF(Participants!G13="","",Participants!G13) -> 20.028842 | F13: =COUNT(Readings!X62:X69) -> 8 | G13: =IF(F13=0,"",MAX(Readings!X62:X69)) -> 5 | H13: =IF(F13=0,"",ROUND(AVERAGE(Readings!X62:X69),0)) -> 1 | I13: =IF(G13="","",IF(G13>=Reference!$B$6,"HIGH",IF(G13>Reference!$B$5,"MODERATE","LOW"))) -> LOW | J13: =IF(COUNT(Readings!Q62:Q69)=0,"",MIN(Readings!Q62:Q69)) -> 153 | K13: =IF(COUNT(Readings!T62:T69)=0,"",MAX(Readings!T62:T69)) -> 1.1077003 | L13: =IF(COUNT(Readings!U62:U69)=0,"",MAX(Readings!U62:U69)) -> 16.40061
A14: 9 | B14: =Participants!B14 -> Aniket | C14: =IF(Participants!E14="","",Participants!E14) -> 180 | D14: =IF(Participants!F14="","",Participants!F14) -> 76 | E14: =IF(Participants!G14="","",Participants!G14) -> 23.45679 | F14: =COUNT(Readings!X70:X77) -> 8 | G14: =IF(F14=0,"",MAX(Readings!X70:X77)) -> 5 | H14: =IF(F14=0,"",ROUND(AVERAGE(Readings!X70:X77),0)) -> 5 | I14: =IF(G14="","",IF(G14>=Reference!$B$6,"HIGH",IF(G14>Reference!$B$5,"MODERATE","LOW"))) -> LOW | J14: =IF(COUNT(Readings!Q70:Q77)=0,"",MIN(Readings!Q70:Q77)) -> 44 | K14: =IF(COUNT(Readings!T70:T77)=0,"",MAX(Readings!T70:T77)) -> 1.0204411 | L14: =IF(COUNT(Readings!U70:U77)=0,"",MAX(Readings!U70:U77)) -> 3.8392708
A15: 10 | B15: =Participants!B15 -> Raghav Garg | C15: =IF(Participants!E15="","",Participants!E15) -> 175 | D15: =IF(Participants!F15="","",Participants!F15) -> 78 | E15: =IF(Participants!G15="","",Participants!G15) -> 25.469388 | F15: =COUNT(Readings!X78:X85) -> 8 | G15: =IF(F15=0,"",MAX(Readings!X78:X85)) -> 5 | H15: =IF(F15=0,"",ROUND(AVERAGE(Readings!X78:X85),0)) -> 1 | I15: =IF(G15="","",IF(G15>=Reference!$B$6,"HIGH",IF(G15>Reference!$B$5,"MODERATE","LOW"))) -> LOW | J15: =IF(COUNT(Readings!Q78:Q85)=0,"",MIN(Readings!Q78:Q85)) -> 161 | K15: =IF(COUNT(Readings!T78:T85)=0,"",MAX(Readings!T78:T85)) -> 1.1381564 | L15: =IF(COUNT(Readings!U78:U85)=0,"",MAX(Readings!U78:U85)) -> 17.941293
A16: 11 | B16: =Participants!B16 -> Kushal Thakur | C16: =IF(Participants!E16="","",Participants!E16) -> 183 | D16: =IF(Participants!F16="","",Participants!F16) -> 82 | E16: =IF(Participants!G16="","",Participants!G16) -> 24.485652 | F16: =COUNT(Readings!X86:X93) -> 8 | G16: =IF(F16=0,"",MAX(Readings!X86:X93)) -> 65 | H16: =IF(F16=0,"",ROUND(AVERAGE(Readings!X86:X93),0)) -> 19 | I16: =IF(G16="","",IF(G16>=Reference!$B$6,"HIGH",IF(G16>Reference!$B$5,"MODERATE","LOW"))) -> MODERATE | J16: =IF(COUNT(Readings!Q86:Q93)=0,"",MIN(Readings!Q86:Q93)) -> 106 | K16: =IF(COUNT(Readings!T86:T93)=0,"",MAX(Readings!T86:T93)) -> 1.5663014 | L16: =IF(COUNT(Readings!U86:U93)=0,"",MAX(Readings!U86:U93)) -> 51.392217
A17: 12 | B17: =Participants!B17 -> Manjot Singh | C17: =IF(Participants!E17="","",Participants!E17) -> 177 | D17: =IF(Participants!F17="","",Participants!F17) -> 67 | E17: =IF(Participants!G17="","",Participants!G17) -> 21.385936 | F17: =COUNT(Readings!X94:X101) -> 8 | G17: =IF(F17=0,"",MAX(Readings!X94:X101)) -> 0 | H17: =IF(F17=0,"",ROUND(AVERAGE(Readings!X94:X101),0)) -> 0 | I17: =IF(G17="","",IF(G17>=Reference!$B$6,"HIGH",IF(G17>Reference!$B$5,"MODERATE","LOW"))) -> LOW | J17: =IF(COUNT(Readings!Q94:Q101)=0,"",MIN(Readings!Q94:Q101)) -> 291 | K17: =IF(COUNT(Readings!T94:T101)=0,"",MAX(Readings!T94:T101)) -> 1.0202451 | L17: =IF(COUNT(Readings!U94:U101)=0,"",MAX(Readings!U94:U101)) -> 2.3937418
A18: 13 | B18: =Participants!B18 -> Tejnoor Singh | C18: =IF(Participants!E18="","",Participants!E18) -> 173 | D18: =IF(Participants!F18="","",Participants!F18) -> 60 | E18: =IF(Participants!G18="","",Participants!G18) -> 20.047446 | F18: =COUNT(Readings!X102:X109) -> 8 | G18: =IF(F18=0,"",MAX(Readings!X102:X109)) -> 5 | H18: =IF(F18=0,"",ROUND(AVERAGE(Readings!X102:X109),0)) -> 1 | I18: =IF(G18="","",IF(G18>=Reference!$B$6,"HIGH",IF(G18>Reference!$B$5,"MODERATE","LOW"))) -> LOW | J18: =IF(COUNT(Readings!Q102:Q109)=0,"",MIN(Readings!Q102:Q109)) -> 165 | K18: =IF(COUNT(Readings!T102:T109)=0,"",MAX(Readings!T102:T109)) -> 1.1209371 | L18: =IF(COUNT(Readings!U102:U109)=0,"",MAX(Readings!U102:U109)) -> 15.690124
A19: 14 | B19: =Participants!B19 -> Ramit Joshi | C19: =IF(Participants!E19="","",Participants!E19) -> 169 | D19: =IF(Participants!F19="","",Participants!F19) -> 58 | E19: =IF(Participants!G19="","",Participants!G19) -> 20.307412 | F19: =COUNT(Readings!X110:X117) -> 8 | G19: =IF(F19=0,"",MAX(Readings!X110:X117)) -> 5 | H19: =IF(F19=0,"",ROUND(AVERAGE(Readings!X110:X117),0)) -> 5 | I19: =IF(G19="","",IF(G19>=Reference!$B$6,"HIGH",IF(G19>Reference!$B$5,"MODERATE","LOW"))) -> LOW | J19: =IF(COUNT(Readings!Q110:Q117)=0,"",MIN(Readings!Q110:Q117)) -> 48 | K19: =IF(COUNT(Readings!T110:T117)=0,"",MAX(Readings!T110:T117)) -> 1.0115829 | L19: =IF(COUNT(Readings!U110:U117)=0,"",MAX(Readings!U110:U117)) -> 3.5014283
A20: 15 | B20: =Participants!B20 -> Kirtan Borana | C20: =IF(Participants!E20="","",Participants!E20) -> 171 | D20: =IF(Participants!F20="","",Participants!F20) -> 74 | E20: =IF(Participants!G20="","",Participants!G20) -> 25.306932 | F20: =COUNT(Readings!X118:X125) -> 8 | G20: =IF(F20=0,"",MAX(Readings!X118:X125)) -> 5 | H20: =IF(F20=0,"",ROUND(AVERAGE(Readings!X118:X125),0)) -> 1 | I20: =IF(G20="","",IF(G20>=Reference!$B$6,"HIGH",IF(G20>Reference!$B$5,"MODERATE","LOW"))) -> LOW | J20: =IF(COUNT(Readings!Q118:Q125)=0,"",MIN(Readings!Q118:Q125)) -> 144 | K20: =IF(COUNT(Readings!T118:T125)=0,"",MAX(Readings!T118:T125)) -> 1.1303539 | L20: =IF(COUNT(Readings!U118:U125)=0,"",MAX(Readings!U118:U125)) -> 16.008435
B22: People with readings | F22: =COUNTIF(F6:F20,">0") -> 15
B23: People rated HIGH | F23: =COUNTIF(I6:I20,"HIGH") -> 1
B24: People rated MODERATE | F24: =COUNTIF(I6:I20,"MODERATE") -> 3
B25: People rated LOW | F25: =COUNTIF(I6:I20,"LOW") -> 11

Sheet Reference
A1: Reference - thresholds and units
A4: Setting | B4: Threshold (at or above) | C4: Points added | D4: Unit / note
A5: Risk LOW up to score | B5: 39 | D5: score 0-39 = LOW
A6: Risk HIGH from score | B6: 70 | D6: score 70-100 = HIGH; 40-69 = MODERATE
A7: Acceleration, normal limit | B7: 1.3 | C7: 10 | D7: g, magnitude of x, y, z
A8: Acceleration, elevated | B8: 1.5 | C8: 25 | D8: g (replaces the 10 points)
A9: Acceleration, high | B9: 2.5 | C9: 40 | D9: g (replaces the 25 points)
A10: Angular velocity, normal limit | B10: 20 | C10: 8 | D10: deg/s, magnitude of x, y, z
A11: Angular velocity, elevated | B11: 30 | C11: 20 | D11: deg/s (replaces the 8 points)
A12: Angular velocity, high | B12: 80 | C12: 40 | D12: deg/s (replaces the 20 points)
A13: Sudden acceleration change | B13: 0.4 | C13: 15 | D13: g, change from the previous reading of the same person
A14: Tilt, elevated | B14: 8 | C14: 5 | D14: deg, sqrt(pitch^2 + roll^2)
A15: Tilt, high | B15: 15 | C15: 10 | D15: deg (replaces the 5 points)
A17: Score = acceleration points + angular-velocity points + sudden-change points + tilt points, capped at 100. Source: fall-risk.js, function fallRiskEngine.
A19: Reading | B19: Unit | C19: Sensor | D19: Range / note
A20: FSR forefoot / midfoot / hindfoot | B20: raw ADC 0-4095 | C20: FSR pressure sensor | D20: uncalibrated count, not newtons
A21: Acceleration x, y, z | B21: g | C21: MPU6050 IMU | D21: about 1.0 g on z when standing still
A22: Angular velocity x, y, z | B22: deg/s | C22: MPU6050 IMU
A23: Pitch, roll | B23: deg | C23: MPU6050 IMU | D23: orientation of the foot
A24: Obstacle distance | B24: cm | C24: HC-SR04 ultrasonic (toe) | D24: typical sensor range 2-400 cm
A25: GPS satellites, fix | B25: count, Y/N | C25: NEO-6M GPS | D25: location needs a fix
